2019-08-07 20:27:49,847 ERROR: Exception on /create_home [POST] [in c:\users\bkettle\onedrive\documents\development\proj\homie\venv\lib\site-packages\flask\app.py:1780]
Traceback (most recent call last):
  File "c:\users\bkettle\onedrive\documents\development\proj\homie\venv\lib\site-packages\sqlalchemy\engine\base.py", line 1244, in _execute_context
    cursor, statement, parameters, context
  File "c:\users\bkettle\onedrive\documents\development\proj\homie\venv\lib\site-packages\sqlalchemy\engine\default.py", line 550, in do_execute
    cursor.execute(statement, parameters)
sqlite3.InterfaceError: Error binding parameter 1 - probably unsupported type.

The above exception was the direct cause of the following exception:

Traceback (most recent call last):
  File "c:\users\bkettle\onedrive\documents\development\proj\homie\venv\lib\site-packages\flask\app.py", line 2311, in wsgi_app
    response = self.full_dispatch_request()
  File "c:\users\bkettle\onedrive\documents\development\proj\homie\venv\lib\site-packages\flask\app.py", line 1834, in full_dispatch_request
    rv = self.handle_user_exception(e)
  File "c:\users\bkettle\onedrive\documents\development\proj\homie\venv\lib\site-packages\flask\app.py", line 1737, in handle_user_exception
    reraise(exc_type, exc_value, tb)
  File "c:\users\bkettle\onedrive\documents\development\proj\homie\venv\lib\site-packages\flask\_compat.py", line 36, in reraise
    raise value
  File "c:\users\bkettle\onedrive\documents\development\proj\homie\venv\lib\site-packages\flask\app.py", line 1832, in full_dispatch_request
    rv = self.dispatch_request()
  File "c:\users\bkettle\onedrive\documents\development\proj\homie\venv\lib\site-packages\flask\app.py", line 1818, in dispatch_request
    return self.view_functions[rule.endpoint](**req.view_args)
  File "C:\Users\bkettle\onedrive\documents\development\proj\homie\app\routes.py", line 90, in create_home
    db.session.commit()
  File "c:\users\bkettle\onedrive\documents\development\proj\homie\venv\lib\site-packages\sqlalchemy\orm\scoping.py", line 162, in do
    return getattr(self.registry(), name)(*args, **kwargs)
  File "c:\users\bkettle\onedrive\documents\development\proj\homie\venv\lib\site-packages\sqlalchemy\orm\session.py", line 1027, in commit
    self.transaction.commit()
  File "c:\users\bkettle\onedrive\documents\development\proj\homie\venv\lib\site-packages\sqlalchemy\orm\session.py", line 494, in commit
    self._prepare_impl()
  File "c:\users\bkettle\onedrive\documents\development\proj\homie\venv\lib\site-packages\sqlalchemy\orm\session.py", line 473, in _prepare_impl
    self.session.flush()
  File "c:\users\bkettle\onedrive\documents\development\proj\homie\venv\lib\site-packages\sqlalchemy\orm\session.py", line 2459, in flush
    self._flush(objects)
  File "c:\users\bkettle\onedrive\documents\development\proj\homie\venv\lib\site-packages\sqlalchemy\orm\session.py", line 2597, in _flush
    transaction.rollback(_capture_exception=True)
  File "c:\users\bkettle\onedrive\documents\development\proj\homie\venv\lib\site-packages\sqlalchemy\util\langhelpers.py", line 68, in __exit__
    compat.reraise(exc_type, exc_value, exc_tb)
  File "c:\users\bkettle\onedrive\documents\development\proj\homie\venv\lib\site-packages\sqlalchemy\util\compat.py", line 154, in reraise
    raise value
  File "c:\users\bkettle\onedrive\documents\development\proj\homie\venv\lib\site-packages\sqlalchemy\orm\session.py", line 2557, in _flush
    flush_context.execute()
  File "c:\users\bkettle\onedrive\documents\development\proj\homie\venv\lib\site-packages\sqlalchemy\orm\unitofwork.py", line 422, in execute
    rec.execute(self)
  File "c:\users\bkettle\onedrive\documents\development\proj\homie\venv\lib\site-packages\sqlalchemy\orm\unitofwork.py", line 589, in execute
    uow,
  File "c:\users\bkettle\onedrive\documents\development\proj\homie\venv\lib\site-packages\sqlalchemy\orm\persistence.py", line 245, in save_obj
    insert,
  File "c:\users\bkettle\onedrive\documents\development\proj\homie\venv\lib\site-packages\sqlalchemy\orm\persistence.py", line 1138, in _emit_insert_statements
    statement, params
  File "c:\users\bkettle\onedrive\documents\development\proj\homie\venv\lib\site-packages\sqlalchemy\engine\base.py", line 988, in execute
    return meth(self, multiparams, params)
  File "c:\users\bkettle\onedrive\documents\development\proj\homie\venv\lib\site-packages\sqlalchemy\sql\elements.py", line 287, in _execute_on_connection
    return connection._execute_clauseelement(self, multiparams, params)
  File "c:\users\bkettle\onedrive\documents\development\proj\homie\venv\lib\site-packages\sqlalchemy\engine\base.py", line 1107, in _execute_clauseelement
    distilled_params,
  File "c:\users\bkettle\onedrive\documents\development\proj\homie\venv\lib\site-packages\sqlalchemy\engine\base.py", line 1248, in _execute_context
    e, statement, parameters, cursor, context
  File "c:\users\bkettle\onedrive\documents\development\proj\homie\venv\lib\site-packages\sqlalchemy\engine\base.py", line 1466, in _handle_dbapi_exception
    util.raise_from_cause(sqlalchemy_exception, exc_info)
  File "c:\users\bkettle\onedrive\documents\development\proj\homie\venv\lib\site-packages\sqlalchemy\util\compat.py", line 399, in raise_from_cause
    reraise(type(exception), exception, tb=exc_tb, cause=cause)
  File "c:\users\bkettle\onedrive\documents\development\proj\homie\venv\lib\site-packages\sqlalchemy\util\compat.py", line 153, in reraise
    raise value.with_traceback(tb)
  File "c:\users\bkettle\onedrive\documents\development\proj\homie\venv\lib\site-packages\sqlalchemy\engine\base.py", line 1244, in _execute_context
    cursor, statement, parameters, context
  File "c:\users\bkettle\onedrive\documents\development\proj\homie\venv\lib\site-packages\sqlalchemy\engine\default.py", line 550, in do_execute
    cursor.execute(statement, parameters)
sqlalchemy.exc.InterfaceError: (sqlite3.InterfaceError) Error binding parameter 1 - probably unsupported type.
[SQL: INSERT INTO home (name, url, user_id, public) VALUES (?, ?, ?, ?)]
[parameters: ("Bob's Shack", <wtforms.fields.core.StringField object at 0x00000232B6FAEBA8>, 1, 1)]
(Background on this error at: http://sqlalche.me/e/rvf5)
2019-08-07 20:28:18,791 INFO: Homie startup [in C:\Users\bkettle\onedrive\documents\development\proj\homie\app\__init__.py:51]
